<?xml version='1.0'?>
<robot name="udacity_bot"
    xmlns:xacro="http://www.ros.org/wiki/xacro">
    <xacro:include filename="$(find slam_project)/urdf/udacity_bot.gazebo"/>
    <link name="robot_footprint"></link>
    <joint name="robot_footprint_joint" type="fixed">
        <origin xyz="0 0 0" rpy="0 0 0"/>
        <parent link="robot_footprint"/>
        <child link="chassis"/>
    </joint>
    <!-- Left wheel -->
    <joint type="continuous" name="left_wheel_hinge">
        <origin xyz="0 0.15 0" rpy="0 0 0"/>
        <child link="left_wheel"/>
        <parent link="chassis"/>
        <axis xyz="0 1 0" rpy="0 0 0"/>
        <limit effort="10000" velocity="1000"/>
        <dynamics damping="1.0" friction="1.0"/>
    </joint>
    <link name='left_wheel'>
        <inertial>
            <mass value="5.0"/>
            <origin xyz="0.0 0 0" rpy=" 0 1.5707 1.5707"/>
            <inertia
          ixx="0.1" ixy="0" ixz="0"
          iyy="0.1" iyz="0"
          izz="0.1"
      />
        </inertial>
        <collision name='left_wheel_collision'>
            <origin xyz="0 0 0" rpy=" 0 1.5707 1.5707"/>
            <geometry>
                <cylinder radius="0.05" length="0.05"/>
            </geometry>
        </collision>
        <visual name='left_wheel_visual'>
            <origin xyz="0 0 0" rpy=" 0 1.5707 1.5707"/>
            <geometry>
                <cylinder radius="0.05" length="0.05"/>
            </geometry>
        </visual>
    </link>
    <!-- Right wheel -->
    <joint type="continuous" name="right_wheel_hinge">
        <origin xyz="0 -0.15 0" rpy="0 0 0"/>
        <child link="right_wheel"/>
        <parent link="chassis"/>
        <axis xyz="0 1 0" rpy="0 0 0"/>
        <limit effort="10000" velocity="1000"/>
        <dynamics damping="1.0" friction="1.0"/>
    </joint>
    <link name='right_wheel'>
        <inertial>
            <mass value="5.0"/>
            <origin xyz="0.0 0 0" rpy=" 0 1.5707 1.5707"/>
            <inertia
          ixx="0.1" ixy="0" ixz="0"
          iyy="0.1" iyz="0"
          izz="0.1"
      />
        </inertial>
        <collision name='right_wheel_collision'>
            <origin xyz="0 0 0" rpy=" 0 1.5707 1.5707"/>
            <geometry>
                <cylinder radius="0.05" length="0.05"/>
            </geometry>
        </collision>
        <visual name='right_wheel_visual'>
            <origin xyz="0 0 0" rpy=" 0 1.5707 1.5707"/>
            <geometry>
                <cylinder radius="0.05" length="0.05"/>
            </geometry>
        </visual>
    </link>
    <!-- Camera -->
    <joint type="fixed" name="camera_joint">
        <origin xyz="0.275 0 0.1" rpy="0 0 0"/>
        <child link="camera"/>
        <parent link="chassis"/>
    </joint>
    
    <link name="camera_rgbd_frame"></link>
    <joint name="camera_rgbd_joint" type="fixed">
        <origin rpy="-${pi/2} 0 -${pi/2}"/>
        <parent link="camera"/>
        <child link="camera_rgbd_frame"/>
    </joint>
    
    <link name='camera'>
        <inertial>
            <mass value="0.1"/>
            <origin xyz="0.0 0 0" rpy=" 0 0 0"/>
            <inertia
          ixx="1e-6" ixy="0" ixz="0"
          iyy="1e-6" iyz="0"
          izz="1e-6"
      />
        </inertial>
        <collision name='camera_collision'>
            <origin xyz="0 0 0" rpy=" 0 0 0"/>
            <geometry>
                <box size="0.05 0.05 0.05"/>
            </geometry>
        </collision>
        <visual name='camera_visual'>
            <origin xyz="0 0 0" rpy=" 0 0 0"/>
            <geometry>
                <box size="0.05 0.05 0.05"/>
            </geometry>
        </visual>
    </link>
    <!-- Laser scanner -->
    <joint type="fixed" name="hokuyo_joint">
        <origin xyz="0 0 0.20" rpy="0 0 0"/>
        <child link="hokuyo"/>
        <parent link="chassis"/>
    </joint>
    <link name='hokuyo'>
        <inertial>
            <mass value="0.1"/>
            <origin xyz="0.0 0 0" rpy=" 0 0 0"/>
            <inertia
          ixx="1e-6" ixy="0" ixz="0"
          iyy="1e-6" iyz="0"
          izz="1e-6"
      />
        </inertial>
        <collision name='hokuyo_collision'>
            <origin xyz="0 0 0" rpy=" 0 0 0"/>
            <geometry>
                <box size="0.1 0.1 0.1"/>
            </geometry>
        </collision>
        <visual name='hokuyo_visual'>
            <origin xyz="0 0 0" rpy=" 0 0 0"/>
            <geometry>
                <mesh filename="package://slam_project/meshes/hokuyo.dae"/>
            </geometry>
        </visual>
    </link>
    <!-- Chassis -->
    <link name='chassis'>
        <pose>0 0 0.1 0 0 0</pose>
        <inertial>
            <mass value="15.0"/>
            <origin xyz="0.0 0 0" rpy=" 0 0 0"/>
            <inertia
          ixx="0.1" ixy="0" ixz="0"
          iyy="0.1" iyz="0"
          izz="0.1"
      />
        </inertial>
        <!--<collision name='collision'>-->
        <!--<origin xyz="0 0 0" rpy=" 0 0 0"/>-->
        <!--<geometry>-->
        <!--<box size=".4 .2 .1"/>-->
        <!--</geometry>-->
        <!--</collision>-->
        <!--<visual name='chassis_visual'>-->
        <!--<origin xyz="0 0 0" rpy=" 0 0 0"/>-->
        <!--<geometry>-->
        <!--<box size=".4 .2 .1"/>-->
        <!--</geometry>-->
        <!--</visual>-->
        <collision name='chassis_collision'>
            <origin xyz="0 0 0.05" rpy=" 0 0 0"/>
            <geometry>
                <cylinder radius="0.25" length="0.15"/>
            </geometry>
        </collision>
        <visual name='chassis_visual'>
            <origin xyz="0 0 0.05" rpy=" 0 0 0"/>
            <geometry>
                <cylinder radius="0.25" length="0.15"/>
            </geometry>
        </visual>
        <collision name='chassis_dome_collision'>
            <origin xyz="0 0 0.1125" rpy=" 0 0 0"/>
            <geometry>
                <sphere radius="0.1"/>
            </geometry>
        </collision>
        <visual name='chassis_dome_visual'>
            <origin xyz="0 0 0.1125" rpy=" 0 0 0"/>
            <geometry>
                <sphere radius="0.1"/>
            </geometry>
        </visual>
        <collision name='back_caster_collision'>
            <origin xyz="-0.15 0 -0.025" rpy=" 0 0 0"/>
            <geometry>
                <sphere radius="0.02499"/>
            </geometry>
        </collision>
        <visual name='back_caster_visual'>
            <origin xyz="-0.15 0 -0.025" rpy=" 0 0 0"/>
            <geometry>
                <sphere radius="0.025"/>
            </geometry>
        </visual>
        <collision name='front_caster_collision'>
            <origin xyz="0.15 0 -0.025" rpy=" 0 0 0"/>
            <geometry>
                <sphere radius="0.02499"/>
            </geometry>
        </collision>
        <visual name='front_caster_visual'>
            <origin xyz="0.15 0 -0.025" rpy=" 0 0 0"/>
            <geometry>
                <sphere radius="0.025"/>
            </geometry>
        </visual>
    </link>
</robot>
